Workbook

Sheet راهنما
A1: لیست لیدهای رستوران‌های تهران — تیم فروش
A3: تاریخ ساخت فایل: 2026-08-27
A4: منبع داده: گوگل‌مپ (جستجوی مرورگر)
A5: پوشش: هر ۲۲ منطقه تهران — یک جستجوی کلی برای هر منطقه (۶ نتیجه اول)
A7: این یعنی چه؟
A8: جمعاً حدود ۱۳۰ رستوران در شیت «لیدها» هست: ۶ رستوران نمونه از هر منطقه.
A9: این یک نمونه‌ی نماینده از هر منطقه است، نه فهرست کامل همه‌ی رستوران‌های آن منطقه —
A10: در واقعیت هر منطقه ده‌ها تا صدها رستوران دارد. گوگل‌مپ برای هر جستجو حداکثر همین چند نتیجه اول را
A11: بدون اسکرول/زوم بیشتر برمی‌گرداند، چون جستجو بر اساس محدوده‌ی نقشه است نه مرز اداری منطقه.
A13: محدودیت‌های شناخته‌شده:
A14: ۱. شماره تلفن فقط برای بعضی رستوران‌ها در نتایج اولیه نمایش داده می‌شود (بقیه باید تک‌تک باز شوند).
A15: ۲. برای پوشش کامل‌تر هر منطقه، باید per منطقه چند جستجوی محله‌ای/خیابانی جدا انجام شود و لیست اسکرول شود؛
... A25: منطقه، نام رستوران، دسته‌بندی، امتیاز، تعداد نظرات، رده قیمت، آدرس، لینک گوگل‌مپ، تلفن، وضعیت لید، یادداشت، تاریخ جمع‌آوری

Sheet لیدها
A1: منطقه | B1: نام رستوران | C1: دسته‌بندی | D1: امتیاز | E1: تعداد نظرات | F1: رده قیمت | G1: آدرس | H1: لینک گوگل‌مپ | I1: تلفن | J1: وضعیت لید | K1: یادداشت | L1: تاریخ جمع‌آوری
A2: ۱ | B2: Divan Restaurant | C2: ایرانی | D2: 4.1 | E2: 495 | G2: Fereshteh St, QCPH+H7W | H2: https://www.google.com/maps/search/Divan+Restaurant+منطقه+۱+تهران | J2: لید جدید | L2: 2026-08-27
A3: ۱ | B3: Mestooran Restaurant | C3: ایرانی | D3: 3.6 | E3: 859 | G3: Bahonar St, RF69+GJ6 | H3: https://www.google.com/maps/search/Mestooran+Restaurant+منطقه+۱+تهران | J3: لید جدید | L3: 2026-08-27
A4: ۱ | B4: Rodizio Brazilian Restaurant | C4: برزیلی | D4: 4 | E4: 205 | G4: Moqadas Ardabili St, QCPF+PM8 | H4: https://www.google.com/maps/search/Rodizio+Brazilian+Restaurant+منطقه+۱+تهران | J4: لید جدید | L4: 2026-08-27
A5: ۱ | B5: Asil Restaurant | C5: ایرانی | D5: 4 | E5: 455 | F5: ۱ تا ۲ میلیون تومان | G5: QCX6+24F | H5: https://www.google.com/maps/search/Asil+Restaurant+منطقه+۱+تهران | J5: لید جدید | L5: 2026-08-27
A6: ۱ | B6: Aghdasieh Restaurant | C6: رستوران | D6: 4 | E6: 628 | G6: خیابان اقدسیه، Artesh Hwy, پلاک ۸، RF2P+52X | H6: https://www.google.com/maps/search/Aghdasieh+Restaurant+منطقه+۱+تهران | J6: لید جدید | L6: 2026-08-27
A7: ۱ | B7: Shandiz Galleria Restaurant | C7: رستوران | D7: 4.1 | E7: 651 | G7: RC54+37P | H7: https://www.google.com/maps/search/Shandiz+Galleria+Restaurant+منطقه+۱+تهران | J7: لید جدید | L7: 2026-08-27
A8: ۲ | B8: رستوران رژیمی باروکال | C8: رستوران | D8: 4.7 | E8: 23 | F8: ۱ تا ۶ میلیون تومان | G8: سعادت‌آباد، میدان کاج، خیابان سرو شرقی، خیابان مجد، کوچه نسترن، پلاک ۴۱ | H8: https://www.google.com/maps/search/رستوران+رژیمی+باروکال+منطقه+۲+تهران | J8: لید جدید | L8: 2026-08-27
A9: ۲ | B9: Tehran Been Restaurant | C9: رستوران | D9: 3.4 | E9: 341 | F9: ۱ میلیون تومان | G9: 17th St, Q9G7+5PC | H9: https://www.google.com/maps/search/Tehran+Been+Restaurant+منطقه+۲+تهران | J9: لید جدید | L9: 2026-08-27
A10: ۲ | B10: Nayeb Restaurant | C10: رستوران | D10: 4 | E10: 401 | F10: ۱ تا ۲ میلیون تومان | G10: Shahid Hassan Tehrani Moghadam Sq, Q9JG+W55 | H10: https://www.google.com/maps/search/Nayeb+Restaurant+منطقه+۲+تهران | J10: لید جدید | L10: 2026-08-27
A11: ۲ | B11: Goli Khanum Restaurant | C11: ایرانی | D11: 3.5 | E11: 84 | G11: Shahrdari, No. 6 | H11: https://www.google.com/maps/search/Goli+Khanum+Restaurant+منطقه+۲+تهران | J11: لید جدید | L11: 2026-08-27
A12: ۲ | B12: Morshed Restaurant | C12: رستوران | D12: 3.9 | E12: 145 | F12: بالای ۱۰ میلیون تومان | G12: Q9HG+W48 | H12: https://www.google.com/maps/search/Morshed+Restaurant+منطقه+۲+تهران | J12: لید جدید | L12: 2026-08-27
A13: ۲ | B13: Mahiye Khoob Restaurant | C13: غذاهای دریایی | D13: 3.9 | E13: 360 | G13: W Sarv Blvd, Q9H6+79J | H13: https://www.google.com/maps/search/Mahiye+Khoob+Restaurant+منطقه+۲+تهران | J13: لید جدید | L13: 2026-08-27
A14: ۳ | B14: Orkideh Restaurant | C14: ایرانی | D14: 4.1 | E14: 56 | G14: Dr Mohammad Mosaddegh St, QC8H+FQ9 | H14: https://www.google.com/maps/search/Orkideh+Restaurant+منطقه+۳+تهران | J14: لید جدید | L14: 2026-08-27
A15: ۳ | B15: Mada'in Arabic Restaurant & Café | C15: خاورمیانه‌ای | D15: 4 | E15: 274 | F15: ۱ تا ۲ میلیون تومان | G15: QC9H+PCR | H15: https://www.google.com/maps/search/Mada'in+Arabic+Restaurant+&+Café+منطقه+۳+تهران | J15: لید جدید | L15: 2026-08-27
A16: ۳ | B16: Parla Italian Restaurant | C16: ایتالیایی | D16: 4.3 | E16: 279 | G16: W Zayandeh Rood St, No. 7 | H16: https://www.google.com/maps/search/Parla+Italian+Restaurant+منطقه+۳+تهران | J16: لید جدید | L16: 2026-08-27
A17: ۳ | B17: Shandiz Jordan Restaurant | C17: ایرانی | D17: 4.3 | E17: 2401 | F17: بالای ۱۰ میلیون تومان | G17: Saba Blvd, QCCF+F44 | H17: https://www.google.com/maps/search/Shandiz+Jordan+Restaurant+منطقه+۳+تهران | J17: لید جدید | L17: 2026-08-27
A18: ۳ | B18: Nouvelle Restaurant | C18: رستوران | D18: 4.4 | E18: 173 | G18: خیابان جردن، بلوار آرش غربی، پلاک ۱۱ | H18: https://www.google.com/maps/search/Nouvelle+Restaurant+منطقه+۳+تهران | J18: لید جدید | L18: 2026-08-27
A19: ۳ | B19: Mohammad restaurant | C19: کباب‌فروشی | D19: 4.3 | E19: 398 | F19: ۱ تا ۵ میلیون تومان | G19: Kolahdooz St, QCHX+W37 | H19: https://www.google.com/maps/search/Mohammad+restaurant+منطقه+۳+تهران | J19: لید جدید | L19: 2026-08-27
A20: ۴ | B20: رستوران سید جلال | C20: رستوران | D20: 3.7 | E20: 26 | F20: ۱ تا ۲ میلیون تومان | G20: 8th Negarestan St, QF54+2H8 | H20: https://www.google.com/maps/search/رستوران+سید+جلال+منطقه+۴+تهران | J20: لید جدید | L20: 2026-08-27
A21: ۴ | B21: Piyaleh Resturant | C21: ایرانی | D21: 3.9 | E21: 213 | F21: ۱ تا ۳ میلیون تومان | G21: N Ostad Hasan Banna Ave, QF2F+VWV | H21: https://www.google.com/maps/search/Piyaleh+Resturant+منطقه+۴+تهران | J21: لید جدید | L21: 2026-08-27
A22: ۴ | B22: 133 Restaurant | C22: رستوران | D22: 4 | E22: 366 | G22: Resalat Hwy, PGJC+WPQ | H22: https://www.google.com/maps/search/133+Restaurant+منطقه+۴+تهران | J22: لید جدید | L22: 2026-08-27
A23: ۴ | B23: کافه رستوران کرنج | C23: رستوران | D23: 4.3 | E23: 92 | F23: ۱ تا ۲ میلیون تومان | G23: تهرانپارس، خیابان ساقدوش، بعد از کوچه یاس | H23: https://www.google.com/maps/search/کافه+رستوران+کرنج+منطقه+۴+تهران | J23: لید جدید | L23: 2026-08-27
A24: ۴ | B24: Roof Lounge | C24: رستوران | D24: 3.1 | E24: 85 | F24: بالای ۱۰ میلیون تومان | G24: 3rd Sq Tehranpars, PGWP+65C | H24: https://www.google.com/maps/search/Roof+Lounge+منطقه+۴+تهران | J24: لید جدید | L24: 2026-08-27
A25: ۴ | B25: Babakhani Restaurant | C25: رستوران | D25: 3.9 | E25: 66 | G25: QC2X+8MP | H25: https://www.google.com/maps/search/Babakhani+Restaurant+منطقه+۴+تهران | J25: لید جدید | L25: 2026-08-27
A26: ۵ | B26: Kandoo Restaurant | C26: رستوران | D26: 4.2 | E26: 110 | F26: ۲ تا ۳ میلیون تومان | G26: مطهری، Q8CJ+2WG | H26: https://www.google.com/maps/search/Kandoo+Restaurant+منطقه+۵+تهران | J26: لید جدید | L26: 2026-08-27
A27: ۵ | B27: Nesen Grill restaurant | C27: رستوران | D27: 4.5 | E27: 158 | F27: ۱ تا ۵ میلیون تومان | G27: P8PH+JFJ | H27: https://www.google.com/maps/search/Nesen+Grill+restaurant+منطقه+۵+تهران | J27: لید جدید | L27: 2026-08-27
A28: ۵ | B28: باغ رستوران شادی | C28: رستوران | D28: 4.5 | E28: 21 | G28: Q76C+CJ3 | H28: https://www.google.com/maps/search/باغ+رستوران+شادی+منطقه+۵+تهران | J28: لید جدید | L28: 2026-08-27
A29: ۵ | B29: Laleh Garden Restaurant | C29: رستوران | D29: 3.6 | E29: 298 | F29: ۲ تا ۸ میلیون تومان | G29: Adl Blvd, Q86J+R59 | H29: https://www.google.com/maps/search/Laleh+Garden+Restaurant+منطقه+۵+تهران | J29: لید جدید | L29: 2026-08-27
A30: ۵ | B30: Hoveyzeh Restaurant | C30: ایرانی | D30: 3.9 | E30: 249 | G30: Q88Q+43W | H30: https://www.google.com/maps/search/Hoveyzeh+Restaurant+منطقه+۵+تهران | J30: لید جدید | L30: 2026-08-27
A31: ۵ | B31: Dees Restaurant | C31: رستوران | D31: 4.1 | E31: 260 | F31: ۱ میلیون تومان | G31: Mirzababaei Blvd, No. ۱۶ | H31: https://www.google.com/maps/search/Dees+Restaurant+منطقه+۵+تهران | J31: لید جدید | L31: 2026-08-27
A32: ۶ | B32: Orkideh Restaurant | C32: رستوران | D32: 4.1 | E32: 1055 | F32: بالای ۱۰ میلیون تومان | G32: Alvand St, PCQ7+3XC | H32: https://www.google.com/maps/search/Orkideh+Restaurant+منطقه+۶+تهران | J32: لید جدید | L32: 2026-08-27
A33: ۶ | B33: Khaneh Koochak Restaurant | C33: رستوران | D33: 3.9 | E33: 471 | G33: P98P+4GW | H33: https://www.google.com/maps/search/Khaneh+Koochak+Restaurant+منطقه+۶+تهران | J33: لید جدید | L33: 2026-08-27
A34: ۶ | B34: Grill Garden | C34: رستوران | D34: 4.5 | E34: 22 | G34: PCW6+3V3 | H34: https://www.google.com/maps/search/Grill+Garden+منطقه+۶+تهران | J34: لید جدید | L34: 2026-08-27
A35: ۶ | B35: Sadr-e Tehran | C35: رستوران | D35: 4.6 | E35: 11 | G35: 26th St, No. 07 | H35: https://www.google.com/maps/search/Sadr-e+Tehran+منطقه+۶+تهران | J35: لید جدید | L35: 2026-08-27
A36: ۶ | B36: Nayeb Vozara | C36: ایرانی | D36: 4 | E36: 75 | F36: بالای ۱۰ میلیون تومان | G36: Vozara St, PCM7+2PM | H36: https://www.google.com/maps/search/Nayeb+Vozara+منطقه+۶+تهران | J36: لید جدید | L36: 2026-08-27
A37: ۶ | B37: Safa Restaurant | C37: رستوران | D37: 4.2 | E37: 78 | F37: ۴ تا ۵ میلیون تومان | G37: N Kargar, P92R+Q89 | H37: https://www.google.com/maps/search/Safa+Restaurant+منطقه+۶+تهران | J37: لید جدید | L37: 2026-08-27
A38: ۷ | B38: Dehbashian Restaurant | C38: رستوران | D38: 4.2 | E38: 252 | G38: S Sohrevardi, PCFP+F64 | H38: https://www.google.com/maps/search/Dehbashian+Restaurant+منطقه+۷+تهران | J38: لید جدید | L38: 2026-08-27
A39: ۷ | B39: Orkideh Restaurant | C39: ایرانی | D39: 4.1 | E39: 56 | G39: Dr Mohammad Mosaddegh St, QC8H+FQ9 | H39: https://www.google.com/maps/search/Orkideh+Restaurant+منطقه+۷+تهران | J39: لید جدید | L39: 2026-08-27
A40: ۷ | B40: Zarech Restaurant | C40: رستوران | D40: 4 | E40: 425 | G40: Sabounchi St, PCJM+Q47 | H40: https://www.google.com/maps/search/Zarech+Restaurant+منطقه+۷+تهران | J40: لید جدید | L40: 2026-08-27
...

Sheet خلاصه مناطق
A1: منطقه | B1: تعداد لید | C1: میانگین امتیاز
A2: ۱ | B2: =COUNTIF(لیدها!A2:A135,A2) -> 6 | C2: =IFERROR(ROUND(AVERAGEIF(لیدها!A2:A135,A2,لیدها!D2:D135),2),"-") -> 3.97
A3: ۲ | B3: =COUNTIF(لیدها!A2:A135,A3) -> 6 | C3: =IFERROR(ROUND(AVERAGEIF(لیدها!A2:A135,A3,لیدها!D2:D135),2),"-") -> 3.9
A4: ۳ | B4: =COUNTIF(لیدها!A2:A135,A4) -> 6 | C4: =IFERROR(ROUND(AVERAGEIF(لیدها!A2:A135,A4,لیدها!D2:D135),2),"-") -> 4.23
A5: ۴ | B5: =COUNTIF(لیدها!A2:A135,A5) -> 6 | C5: =IFERROR(ROUND(AVERAGEIF(لیدها!A2:A135,A5,لیدها!D2:D135),2),"-") -> 3.82
A6: ۵ | B6: =COUNTIF(لیدها!A2:A135,A6) -> 6 | C6: =IFERROR(ROUND(AVERAGEIF(لیدها!A2:A135,A6,لیدها!D2:D135),2),"-") -> 4.13
A7: ۶ | B7: =COUNTIF(لیدها!A2:A135,A7) -> 6 | C7: =IFERROR(ROUND(AVERAGEIF(لیدها!A2:A135,A7,لیدها!D2:D135),2),"-") -> 4.22
A8: ۷ | B8: =COUNTIF(لیدها!A2:A135,A8) -> 6 | C8: =IFERROR(ROUND(AVERAGEIF(لیدها!A2:A135,A8,لیدها!D2:D135),2),"-") -> 4.2
A9: ۸ | B9: =COUNTIF(لیدها!A2:A135,A9) -> 6 | C9: =IFERROR(ROUND(AVERAGEIF(لیدها!A2:A135,A9,لیدها!D2:D135),2),"-") -> 4.23
A10: ۹ | B10: =COUNTIF(لیدها!A2:A135,A10) -> 6 | C10: =IFERROR(ROUND(AVERAGEIF(لیدها!A2:A135,A10,لیدها!D2:D135),2),"-") -> 4.48
A11: ۱۰ | B11: =COUNTIF(لیدها!A2:A135,A11) -> 6 | C11: =IFERROR(ROUND(AVERAGEIF(لیدها!A2:A135,A11,لیدها!D2:D135),2),"-") -> 3.75
A12: ۱۱ | B12: =COUNTIF(لیدها!A2:A135,A12) -> 6 | C12: =IFERROR(ROUND(AVERAGEIF(لیدها!A2:A135,A12,لیدها!D2:D135),2),"-") -> 4.03
A13: ۱۲ | B13: =COUNTIF(لیدها!A2:A135,A13) -> 6 | C13: =IFERROR(ROUND(AVERAGEIF(لیدها!A2:A135,A13,لیدها!D2:D135),2),"-") -> 4.23
A14: ۱۳ | B14: =COUNTIF(لیدها!A2:A135,A14) -> 6 | C14: =IFERROR(ROUND(AVERAGEIF(لیدها!A2:A135,A14,لیدها!D2:D135),2),"-") -> 3.83
A15: ۱۴ | B15: =COUNTIF(لیدها!A2:A135,A15) -> 6 | C15: =IFERROR(ROUND(AVERAGEIF(لیدها!A2:A135,A15,لیدها!D2:D135),2),"-") -> 4.32
A16: ۱۵ | B16: =COUNTIF(لیدها!A2:A135,A16) -> 5 | C16: =IFERROR(ROUND(AVERAGEIF(لیدها!A2:A135,A16,لیدها!D2:D135),2),"-") -> 4.2
A17: ۱۶ | B17: =COUNTIF(لیدها!A2:A135,A17) -> 6 | C17: =IFERROR(ROUND(AVERAGEIF(لیدها!A2:A135,A17,لیدها!D2:D135),2),"-") -> 3.75
A18: ۱۷ | B18: =COUNTIF(لیدها!A2:A135,A18) -> 6 | C18: =IFERROR(ROUND(AVERAGEIF(لیدها!A2:A135,A18,لیدها!D2:D135),2),"-") -> 4.23
A19: ۱۸ | B19: =COUNTIF(لیدها!A2:A135,A19) -> 6 | C19: =IFERROR(ROUND(AVERAGEIF(لیدها!A2:A135,A19,لیدها!D2:D135),2),"-") -> 4.33
A20: ۱۹ | B20: =COUNTIF(لیدها!A2:A135,A20) -> 6 | C20: =IFERROR(ROUND(AVERAGEIF(لیدها!A2:A135,A20,لیدها!D2:D135),2),"-") -> 3.73
A21: ۲۰ | B21: =COUNTIF(لیدها!A2:A135,A21) -> 6 | C21: =IFERROR(ROUND(AVERAGEIF(لیدها!A2:A135,A21,لیدها!D2:D135),2),"-") -> 4.53
A22: ۲۱ | B22: =COUNTIF(لیدها!A2:A135,A22) -> 6 | C22: =IFERROR(ROUND(AVERAGEIF(لیدها!A2:A135,A22,لیدها!D2:D135),2),"-") -> 4.05
A23: ۲۲ | B23: =COUNTIF(لیدها!A2:A135,A23) -> 9 | C23: =IFERROR(ROUND(AVERAGEIF(لیدها!A2:A135,A23,لیدها!D2:D135),2),"-") -> 3.98
